[ERROR] 2018-03-08 18:43:08,786 /home/marclane/Desktop/Targenda/targendaapi/venv/lib/python3.5/site-packages/django/core/handlers/exception.py:74 Invalid HTTP_HOST header: 'localhost:8000'. You may need to add 'localhost' to ALLOWED_HOSTS.
[ERROR] 2018-03-08 18:43:08,789 /home/marclane/Desktop/Targenda/targendaapi/venv/lib/python3.5/site-packages/django/core/handlers/exception.py:118 Internal Server Error: /api/v1/calendar/request
Traceback (most recent call last):
  File "/home/marclane/Desktop/Targenda/targendaapi/venv/lib/python3.5/site-packages/django/core/handlers/exception.py", line 35, in inner
    response = get_response(request)
  File "/home/marclane/Desktop/Targenda/targendaapi/venv/lib/python3.5/site-packages/django/utils/deprecation.py", line 93, in __call__
    response = self.process_request(request)
  File "/home/marclane/Desktop/Targenda/targendaapi/venv/lib/python3.5/site-packages/django/middleware/common.py", line 55, in process_request
    host = request.get_host()
  File "/home/marclane/Desktop/Targenda/targendaapi/venv/lib/python3.5/site-packages/django/http/request.py", line 105, in get_host
    raise DisallowedHost(msg)
django.core.exceptions.DisallowedHost: Invalid HTTP_HOST header: 'localhost:8000'. You may need to add 'localhost' to ALLOWED_HOSTS.

During handling of the above exception, another exception occurred:

Traceback (most recent call last):
  File "/home/marclane/Desktop/Targenda/targendaapi/venv/lib/python3.5/site-packages/django/template/utils.py", line 64, in __getitem__
    return self._engines[alias]
KeyError: 'django'

During handling of the above exception, another exception occurred:

Traceback (most recent call last):
  File "/home/marclane/Desktop/Targenda/targendaapi/venv/lib/python3.5/site-packages/django/template/backends/django.py", line 121, in get_package_libraries
    module = import_module(entry[1])
  File "/home/marclane/Desktop/Targenda/targendaapi/venv/lib/python3.5/importlib/__init__.py", line 126, in import_module
    return _bootstrap._gcd_import(name[level:], package, level)
  File "<frozen importlib._bootstrap>", line 986, in _gcd_import
  File "<frozen importlib._bootstrap>", line 969, in _find_and_load
  File "<frozen importlib._bootstrap>", line 958, in _find_and_load_unlocked
  File "<frozen importlib._bootstrap>", line 673, in _load_unlocked
  File "<frozen importlib._bootstrap_external>", line 665, in exec_module
  File "<frozen importlib._bootstrap>", line 222, in _call_with_frames_removed
  File "/home/marclane/Desktop/Targenda/targendaapi/venv/lib/python3.5/site-packages/crispy_forms/templatetags/crispy_forms_tags.py", line 11, in <module>
    from crispy_forms.helper import FormHelper
  File "/home/marclane/Desktop/Targenda/targendaapi/venv/lib/python3.5/site-packages/crispy_forms/helper.py", line 4, in <module>
    from django.core.urlresolvers import reverse, NoReverseMatch
ImportError: No module named 'django.core.urlresolvers'

During handling of the above exception, another exception occurred:

Traceback (most recent call last):
  File "/home/marclane/Desktop/Targenda/targendaapi/venv/lib/python3.5/site-packages/django/core/handlers/exception.py", line 99, in get_exception_response
    response = callback(request, **dict(param_dict, exception=exception))
  File "/home/marclane/Desktop/Targenda/targendaapi/venv/lib/python3.5/site-packages/django/utils/decorators.py", line 142, in _wrapped_view
    response = view_func(request, *args, **kwargs)
  File "/home/marclane/Desktop/Targenda/targendaapi/venv/lib/python3.5/site-packages/django/views/defaults.py", line 87, in bad_request
    template = loader.get_template(template_name)
  File "/home/marclane/Desktop/Targenda/targendaapi/venv/lib/python3.5/site-packages/django/template/loader.py", line 12, in get_template
    engines = _engine_list(using)
  File "/home/marclane/Desktop/Targenda/targendaapi/venv/lib/python3.5/site-packages/django/template/loader.py", line 66, in _engine_list
    return engines.all() if using is None else [engines[using]]
  File "/home/marclane/Desktop/Targenda/targendaapi/venv/lib/python3.5/site-packages/django/template/utils.py", line 88, in all
    return [self[alias] for alias in self]
  File "/home/marclane/Desktop/Targenda/targendaapi/venv/lib/python3.5/site-packages/django/template/utils.py", line 88, in <listcomp>
    return [self[alias] for alias in self]
  File "/home/marclane/Desktop/Targenda/targendaapi/venv/lib/python3.5/site-packages/django/template/utils.py", line 79, in __getitem__
    engine = engine_cls(params)
  File "/home/marclane/Desktop/Targenda/targendaapi/venv/lib/python3.5/site-packages/django/template/backends/django.py", line 25, in __init__
    options['libraries'] = self.get_templatetag_libraries(libraries)
  File "/home/marclane/Desktop/Targenda/targendaapi/venv/lib/python3.5/site-packages/django/template/backends/django.py", line 43, in get_templatetag_libraries
    libraries = get_installed_libraries()
  File "/home/marclane/Desktop/Targenda/targendaapi/venv/lib/python3.5/site-packages/django/template/backends/django.py", line 108, in get_installed_libraries
    for name in get_package_libraries(pkg):
  File "/home/marclane/Desktop/Targenda/targendaapi/venv/lib/python3.5/site-packages/django/template/backends/django.py", line 125, in get_package_libraries
    "trying to load '%s': %s" % (entry[1], e)
django.template.library.InvalidTemplateLibrary: Invalid template library specified. ImportError raised when trying to load 'crispy_forms.templatetags.crispy_forms_tags': No module named 'django.core.urlresolvers'
[ERROR] 2018-03-08 18:43:08,941 /home/marclane/Desktop/Targenda/targendaapi/venv/lib/python3.5/site-packages/django/core/handlers/exception.py:118 Internal Server Error: /api/v1/calendar/request
Traceback (most recent call last):
  File "/home/marclane/Desktop/Targenda/targendaapi/venv/lib/python3.5/site-packages/django/core/handlers/exception.py", line 35, in inner
    response = get_response(request)
  File "/home/marclane/Desktop/Targenda/targendaapi/venv/lib/python3.5/site-packages/django/utils/deprecation.py", line 93, in __call__
    response = self.process_request(request)
  File "/home/marclane/Desktop/Targenda/targendaapi/venv/lib/python3.5/site-packages/django/middleware/common.py", line 55, in process_request
    host = request.get_host()
  File "/home/marclane/Desktop/Targenda/targendaapi/venv/lib/python3.5/site-packages/django/http/request.py", line 105, in get_host
    raise DisallowedHost(msg)
django.core.exceptions.DisallowedHost: Invalid HTTP_HOST header: 'localhost:8000'. You may need to add 'localhost' to ALLOWED_HOSTS.

During handling of the above exception, another exception occurred:

Traceback (most recent call last):
  File "/home/marclane/Desktop/Targenda/targendaapi/venv/lib/python3.5/site-packages/django/template/utils.py", line 64, in __getitem__
    return self._engines[alias]
KeyError: 'django'

During handling of the above exception, another exception occurred:

Traceback (most recent call last):
  File "/home/marclane/Desktop/Targenda/targendaapi/venv/lib/python3.5/site-packages/django/template/backends/django.py", line 121, in get_package_libraries
    module = import_module(entry[1])
  File "/home/marclane/Desktop/Targenda/targendaapi/venv/lib/python3.5/importlib/__init__.py", line 126, in import_module
    return _bootstrap._gcd_import(name[level:], package, level)
  File "<frozen importlib._bootstrap>", line 986, in _gcd_import
  File "<frozen importlib._bootstrap>", line 969, in _find_and_load
  File "<frozen importlib._bootstrap>", line 958, in _find_and_load_unlocked
  File "<frozen importlib._bootstrap>", line 673, in _load_unlocked
  File "<frozen importlib._bootstrap_external>", line 665, in exec_module
  File "<frozen importlib._bootstrap>", line 222, in _call_with_frames_removed
  File "/home/marclane/Desktop/Targenda/targendaapi/venv/lib/python3.5/site-packages/crispy_forms/templatetags/crispy_forms_tags.py", line 11, in <module>
    from crispy_forms.helper import FormHelper
  File "/home/marclane/Desktop/Targenda/targendaapi/venv/lib/python3.5/site-packages/crispy_forms/helper.py", line 4, in <module>
    from django.core.urlresolvers import reverse, NoReverseMatch
ImportError: No module named 'django.core.urlresolvers'

During handling of the above exception, another exception occurred:

Traceback (most recent call last):
  File "/home/marclane/Desktop/Targenda/targendaapi/venv/lib/python3.5/site-packages/django/core/handlers/exception.py", line 99, in get_exception_response
    response = callback(request, **dict(param_dict, exception=exception))
  File "/home/marclane/Desktop/Targenda/targendaapi/venv/lib/python3.5/site-packages/django/utils/decorators.py", line 142, in _wrapped_view
    response = view_func(request, *args, **kwargs)
  File "/home/marclane/Desktop/Targenda/targendaapi/venv/lib/python3.5/site-packages/django/views/defaults.py", line 87, in bad_request
    template = loader.get_template(template_name)
  File "/home/marclane/Desktop/Targenda/targendaapi/venv/lib/python3.5/site-packages/django/template/loader.py", line 12, in get_template
    engines = _engine_list(using)
  File "/home/marclane/Desktop/Targenda/targendaapi/venv/lib/python3.5/site-packages/django/template/loader.py", line 66, in _engine_list
    return engines.all() if using is None else [engines[using]]
  File "/home/marclane/Desktop/Targenda/targendaapi/venv/lib/python3.5/site-packages/django/template/utils.py", line 88, in all
    return [self[alias] for alias in self]
  File "/home/marclane/Desktop/Targenda/targendaapi/venv/lib/python3.5/site-packages/django/template/utils.py", line 88, in <listcomp>
    return [self[alias] for alias in self]
  File "/home/marclane/Desktop/Targenda/targendaapi/venv/lib/python3.5/site-packages/django/template/utils.py", line 79, in __getitem__
    engine = engine_cls(params)
  File "/home/marclane/Desktop/Targenda/targendaapi/venv/lib/python3.5/site-packages/django/template/backends/django.py", line 25, in __init__
    options['libraries'] = self.get_templatetag_libraries(libraries)
  File "/home/marclane/Desktop/Targenda/targendaapi/venv/lib/python3.5/site-packages/django/template/backends/django.py", line 43, in get_templatetag_libraries
    libraries = get_installed_libraries()
  File "/home/marclane/Desktop/Targenda/targendaapi/venv/lib/python3.5/site-packages/django/template/backends/django.py", line 108, in get_installed_libraries
    for name in get_package_libraries(pkg):
  File "/home/marclane/Desktop/Targenda/targendaapi/venv/lib/python3.5/site-packages/django/template/backends/django.py", line 125, in get_package_libraries
    "trying to load '%s': %s" % (entry[1], e)
django.template.library.InvalidTemplateLibrary: Invalid template library specified. ImportError raised when trying to load 'crispy_forms.templatetags.crispy_forms_tags': No module named 'django.core.urlresolvers'

During handling of the above exception, another exception occurred:

Traceback (most recent call last):
  File "/home/marclane/Desktop/Targenda/targendaapi/venv/lib/python3.5/site-packages/django/template/utils.py", line 64, in __getitem__
    return self._engines[alias]
KeyError: 'django'

During handling of the above exception, another exception occurred:

Traceback (most recent call last):
  File "/home/marclane/Desktop/Targenda/targendaapi/venv/lib/python3.5/site-packages/django/template/backends/django.py", line 121, in get_package_libraries
    module = import_module(entry[1])
  File "/home/marclane/Desktop/Targenda/targendaapi/venv/lib/python3.5/importlib/__init__.py", line 126, in import_module
    return _bootstrap._gcd_import(name[level:], package, level)
  File "<frozen importlib._bootstrap>", line 986, in _gcd_import
  File "<frozen importlib._bootstrap>", line 969, in _find_and_load
  File "<frozen importlib._bootstrap>", line 958, in _find_and_load_unlocked
  File "<frozen importlib._bootstrap>", line 673, in _load_unlocked
  File "<frozen importlib._bootstrap_external>", line 665, in exec_module
  File "<frozen importlib._bootstrap>", line 222, in _call_with_frames_removed
  File "/home/marclane/Desktop/Targenda/targendaapi/venv/lib/python3.5/site-packages/crispy_forms/templatetags/crispy_forms_tags.py", line 11, in <module>
    from crispy_forms.helper import FormHelper
  File "/home/marclane/Desktop/Targenda/targendaapi/venv/lib/python3.5/site-packages/crispy_forms/helper.py", line 4, in <module>
    from django.core.urlresolvers import reverse, NoReverseMatch
ImportError: No module named 'django.core.urlresolvers'

During handling of the above exception, another exception occurred:

Traceback (most recent call last):
  File "/home/marclane/Desktop/Targenda/targendaapi/venv/lib/python3.5/site-packages/django/core/handlers/exception.py", line 35, in inner
    response = get_response(request)
  File "/home/marclane/Desktop/Targenda/targendaapi/venv/lib/python3.5/site-packages/django/utils/deprecation.py", line 95, in __call__
    response = self.get_response(request)
  File "/home/marclane/Desktop/Targenda/targendaapi/venv/lib/python3.5/site-packages/django/core/handlers/exception.py", line 37, in inner
    response = response_for_exception(request, exc)
  File "/home/marclane/Desktop/Targenda/targendaapi/venv/lib/python3.5/site-packages/django/core/handlers/exception.py", line 79, in response_for_exception
    response = get_exception_response(request, get_resolver(get_urlconf()), 400, exc)
  File "/home/marclane/Desktop/Targenda/targendaapi/venv/lib/python3.5/site-packages/django/core/handlers/exception.py", line 102, in get_exception_response
    response = handle_uncaught_exception(request, resolver, sys.exc_info())
  File "/home/marclane/Desktop/Targenda/targendaapi/venv/lib/python3.5/site-packages/django/core/handlers/exception.py", line 126, in handle_uncaught_exception
    return callback(request, **param_dict)
  File "/home/marclane/Desktop/Targenda/targendaapi/venv/lib/python3.5/site-packages/django/utils/decorators.py", line 142, in _wrapped_view
    response = view_func(request, *args, **kwargs)
  File "/home/marclane/Desktop/Targenda/targendaapi/venv/lib/python3.5/site-packages/django/views/defaults.py", line 69, in server_error
    template = loader.get_template(template_name)
  File "/home/marclane/Desktop/Targenda/targendaapi/venv/lib/python3.5/site-packages/django/template/loader.py", line 12, in get_template
    engines = _engine_list(using)
  File "/home/marclane/Desktop/Targenda/targendaapi/venv/lib/python3.5/site-packages/django/template/loader.py", line 66, in _engine_list
    return engines.all() if using is None else [engines[using]]
  File "/home/marclane/Desktop/Targenda/targendaapi/venv/lib/python3.5/site-packages/django/template/utils.py", line 88, in all
    return [self[alias] for alias in self]
  File "/home/marclane/Desktop/Targenda/targendaapi/venv/lib/python3.5/site-packages/django/template/utils.py", line 88, in <listcomp>
    return [self[alias] for alias in self]
  File "/home/marclane/Desktop/Targenda/targendaapi/venv/lib/python3.5/site-packages/django/template/utils.py", line 79, in __getitem__
    engine = engine_cls(params)
  File "/home/marclane/Desktop/Targenda/targendaapi/venv/lib/python3.5/site-packages/django/template/backends/django.py", line 25, in __init__
    options['libraries'] = self.get_templatetag_libraries(libraries)
  File "/home/marclane/Desktop/Targenda/targendaapi/venv/lib/python3.5/site-packages/django/template/backends/django.py", line 43, in get_templatetag_libraries
    libraries = get_installed_libraries()
  File "/home/marclane/Desktop/Targenda/targendaapi/venv/lib/python3.5/site-packages/django/template/backends/django.py", line 108, in get_installed_libraries
    for name in get_package_libraries(pkg):
  File "/home/marclane/Desktop/Targenda/targendaapi/venv/lib/python3.5/site-packages/django/template/backends/django.py", line 125, in get_package_libraries
    "trying to load '%s': %s" % (entry[1], e)
django.template.library.InvalidTemplateLibrary: Invalid template library specified. ImportError raised when trying to load 'crispy_forms.templatetags.crispy_forms_tags': No module named 'django.core.urlresolvers'
[ERROR] 2018-03-08 18:43:09,052 /home/marclane/Desktop/Targenda/targendaapi/venv/lib/python3.5/site-packages/django/core/handlers/exception.py:118 Internal Server Error: /api/v1/calendar/request
Traceback (most recent call last):
  File "/home/marclane/Desktop/Targenda/targendaapi/venv/lib/python3.5/site-packages/django/core/handlers/exception.py", line 35, in inner
    response = get_response(request)
  File "/home/marclane/Desktop/Targenda/targendaapi/venv/lib/python3.5/site-packages/django/utils/deprecation.py", line 93, in __call__
    response = self.process_request(request)
  File "/home/marclane/Desktop/Targenda/targendaapi/venv/lib/python3.5/site-packages/django/middleware/common.py", line 55, in process_request
    host = request.get_host()
  File "/home/marclane/Desktop/Targenda/targendaapi/venv/lib/python3.5/site-packages/django/http/request.py", line 105, in get_host
    raise DisallowedHost(msg)
django.core.exceptions.DisallowedHost: Invalid HTTP_HOST header: 'localhost:8000'. You may need to add 'localhost' to ALLOWED_HOSTS.

During handling of the above exception, another exception occurred:

Traceback (most recent call last):
  File "/home/marclane/Desktop/Targenda/targendaapi/venv/lib/python3.5/site-packages/django/template/utils.py", line 64, in __getitem__
    return self._engines[alias]
KeyError: 'django'

During handling of the above exception, another exception occurred:

Traceback (most recent call last):
  File "/home/marclane/Desktop/Targenda/targendaapi/venv/lib/python3.5/site-packages/django/template/backends/django.py", line 121, in get_package_libraries
    module = import_module(entry[1])
  File "/home/marclane/Desktop/Targenda/targendaapi/venv/lib/python3.5/importlib/__init__.py", line 126, in import_module
    return _bootstrap._gcd_import(name[level:], package, level)
  File "<frozen importlib._bootstrap>", line 986, in _gcd_import
  File "<frozen importlib._bootstrap>", line 969, in _find_and_load
  File "<frozen importlib._bootstrap>", line 958, in _find_and_load_unlocked
  File "<frozen importlib._bootstrap>", line 673, in _load_unlocked
  File "<frozen importlib._bootstrap_external>", line 665, in exec_module
  File "<frozen importlib._bootstrap>", line 222, in _call_with_frames_removed
  File "/home/marclane/Desktop/Targenda/targendaapi/venv/lib/python3.5/site-packages/crispy_forms/templatetags/crispy_forms_tags.py", line 11, in <module>
    from crispy_forms.helper import FormHelper
  File "/home/marclane/Desktop/Targenda/targendaapi/venv/lib/python3.5/site-packages/crispy_forms/helper.py", line 4, in <module>
    from django.core.urlresolvers import reverse, NoReverseMatch
ImportError: No module named 'django.core.urlresolvers'

During handling of the above exception, another exception occurred:

Traceback (most recent call last):
  File "/home/marclane/Desktop/Targenda/targendaapi/venv/lib/python3.5/site-packages/django/core/handlers/exception.py", line 99, in get_exception_response
    response = callback(request, **dict(param_dict, exception=exception))
  File "/home/marclane/Desktop/Targenda/targendaapi/venv/lib/python3.5/site-packages/django/utils/decorators.py", line 142, in _wrapped_view
    response = view_func(request, *args, **kwargs)
  File "/home/marclane/Desktop/Targenda/targendaapi/venv/lib/python3.5/site-packages/django/views/defaults.py", line 87, in bad_request
    template = loader.get_template(template_name)
  File "/home/marclane/Desktop/Targenda/targendaapi/venv/lib/python3.5/site-packages/django/template/loader.py", line 12, in get_template
    engines = _engine_list(using)
  File "/home/marclane/Desktop/Targenda/targendaapi/venv/lib/python3.5/site-packages/django/template/loader.py", line 66, in _engine_list
    return engines.all() if using is None else [engines[using]]
  File "/home/marclane/Desktop/Targenda/targendaapi/venv/lib/python3.5/site-packages/django/template/utils.py", line 88, in all
    return [self[alias] for alias in self]
  File "/home/marclane/Desktop/Targenda/targendaapi/venv/lib/python3.5/site-packages/django/template/utils.py", line 88, in <listcomp>
    return [self[alias] for alias in self]
  File "/home/marclane/Desktop/Targenda/targendaapi/venv/lib/python3.5/site-packages/django/template/utils.py", line 79, in __getitem__
    engine = engine_cls(params)
  File "/home/marclane/Desktop/Targenda/targendaapi/venv/lib/python3.5/site-packages/django/template/backends/django.py", line 25, in __init__
    options['libraries'] = self.get_templatetag_libraries(libraries)
  File "/home/marclane/Desktop/Targenda/targendaapi/venv/lib/python3.5/site-packages/django/template/backends/django.py", line 43, in get_templatetag_libraries
    libraries = get_installed_libraries()
  File "/home/marclane/Desktop/Targenda/targendaapi/venv/lib/python3.5/site-packages/django/template/backends/django.py", line 108, in get_installed_libraries
    for name in get_package_libraries(pkg):
  File "/home/marclane/Desktop/Targenda/targendaapi/venv/lib/python3.5/site-packages/django/template/backends/django.py", line 125, in get_package_libraries
    "trying to load '%s': %s" % (entry[1], e)
django.template.library.InvalidTemplateLibrary: Invalid template library specified. ImportError raised when trying to load 'crispy_forms.templatetags.crispy_forms_tags': No module named 'django.core.urlresolvers'

During handling of the above exception, another exception occurred:

Traceback (most recent call last):
  File "/home/marclane/Desktop/Targenda/targendaapi/venv/lib/python3.5/site-packages/django/template/utils.py", line 64, in __getitem__
    return self._engines[alias]
KeyError: 'django'

During handling of the above exception, another exception occurred:

Traceback (most recent call last):
  File "/home/marclane/Desktop/Targenda/targendaapi/venv/lib/python3.5/site-packages/django/template/backends/django.py", line 121, in get_package_libraries
    module = import_module(entry[1])
  File "/home/marclane/Desktop/Targenda/targendaapi/venv/lib/python3.5/importlib/__init__.py", line 126, in import_module
    return _bootstrap._gcd_import(name[level:], package, level)
  File "<frozen importlib._bootstrap>", line 986, in _gcd_import
  File "<frozen importlib._bootstrap>", line 969, in _find_and_load
  File "<frozen importlib._bootstrap>", line 958, in _find_and_load_unlocked
  File "<frozen importlib._bootstrap>", line 673, in _load_unlocked
  File "<frozen importlib._bootstrap_external>", line 665, in exec_module
  File "<frozen importlib._bootstrap>", line 222, in _call_with_frames_removed
  File "/home/marclane/Desktop/Targenda/targendaapi/venv/lib/python3.5/site-packages/crispy_forms/templatetags/crispy_forms_tags.py", line 11, in <module>
    from crispy_forms.helper import FormHelper
  File "/home/marclane/Desktop/Targenda/targendaapi/venv/lib/python3.5/site-packages/crispy_forms/helper.py", line 4, in <module>
    from django.core.urlresolvers import reverse, NoReverseMatch
ImportError: No module named 'django.core.urlresolvers'

During handling of the above exception, another exception occurred:

Traceback (most recent call last):
  File "/home/marclane/Desktop/Targenda/targendaapi/venv/lib/python3.5/site-packages/django/core/handlers/exception.py", line 35, in inner
    response = get_response(request)
  File "/home/marclane/Desktop/Targenda/targendaapi/venv/lib/python3.5/site-packages/django/utils/deprecation.py", line 95, in __call__
    response = self.get_response(request)
  File "/home/marclane/Desktop/Targenda/targendaapi/venv/lib/python3.5/site-packages/django/core/handlers/exception.py", line 37, in inner
    response = response_for_exception(request, exc)
  File "/home/marclane/Desktop/Targenda/targendaapi/venv/lib/python3.5/site-packages/django/core/handlers/exception.py", line 79, in response_for_exception
    response = get_exception_response(request, get_resolver(get_urlconf()), 400, exc)
  File "/home/marclane/Desktop/Targenda/targendaapi/venv/lib/python3.5/site-packages/django/core/handlers/exception.py", line 102, in get_exception_response
    response = handle_uncaught_exception(request, resolver, sys.exc_info())
  File "/home/marclane/Desktop/Targenda/targendaapi/venv/lib/python3.5/site-packages/django/core/handlers/exception.py", line 126, in handle_uncaught_exception
    return callback(request, **param_dict)
  File "/home/marclane/Desktop/Targenda/targendaapi/venv/lib/python3.5/site-packages/django/utils/decorators.py", line 142, in _wrapped_view
    response = view_func(request, *args, **kwargs)
  File "/home/marclane/Desktop/Targenda/targendaapi/venv/lib/python3.5/site-packages/django/views/defaults.py", line 69, in server_error
    template = loader.get_template(template_name)
  File "/home/marclane/Desktop/Targenda/targendaapi/venv/lib/python3.5/site-packages/django/template/loader.py", line 12, in get_template
    engines = _engine_list(using)
  File "/home/marclane/Desktop/Targenda/targendaapi/venv/lib/python3.5/site-packages/django/template/loader.py", line 66, in _engine_list
    return engines.all() if using is None else [engines[using]]
  File "/home/marclane/Desktop/Targenda/targendaapi/venv/lib/python3.5/site-packages/django/template/utils.py", line 88, in all
    return [self[alias] for alias in self]
  File "/home/marclane/Desktop/Targenda/targendaapi/venv/lib/python3.5/site-packages/django/template/utils.py", line 88, in <listcomp>
    return [self[alias] for alias in self]
  File "/home/marclane/Desktop/Targenda/targendaapi/venv/lib/python3.5/site-packages/django/template/utils.py", line 79, in __getitem__
    engine = engine_cls(params)
  File "/home/marclane/Desktop/Targenda/targendaapi/venv/lib/python3.5/site-packages/django/template/backends/django.py", line 25, in __init__
    options['libraries'] = self.get_templatetag_libraries(libraries)
  File "/home/marclane/Desktop/Targenda/targendaapi/venv/lib/python3.5/site-packages/django/template/backends/django.py", line 43, in get_templatetag_libraries
    libraries = get_installed_libraries()
  File "/home/marclane/Desktop/Targenda/targendaapi/venv/lib/python3.5/site-packages/django/template/backends/django.py", line 108, in get_installed_libraries
    for name in get_package_libraries(pkg):
  File "/home/marclane/Desktop/Targenda/targendaapi/venv/lib/python3.5/site-packages/django/template/backends/django.py", line 125, in get_package_libraries
    "trying to load '%s': %s" % (entry[1], e)
django.template.library.InvalidTemplateLibrary: Invalid template library specified. ImportError raised when trying to load 'crispy_forms.templatetags.crispy_forms_tags': No module named 'django.core.urlresolvers'

During handling of the above exception, another exception occurred:

Traceback (most recent call last):
  File "/home/marclane/Desktop/Targenda/targendaapi/venv/lib/python3.5/site-packages/django/template/utils.py", line 64, in __getitem__
    return self._engines[alias]
KeyError: 'django'

During handling of the above exception, another exception occurred:

Traceback (most recent call last):
  File "/home/marclane/Desktop/Targenda/targendaapi/venv/lib/python3.5/site-packages/django/template/backends/django.py", line 121, in get_package_libraries
    module = import_module(entry[1])
  File "/home/marclane/Desktop/Targenda/targendaapi/venv/lib/python3.5/importlib/__init__.py", line 126, in import_module
    return _bootstrap._gcd_import(name[level:], package, level)
  File "<frozen importlib._bootstrap>", line 986, in _gcd_import
  File "<frozen importlib._bootstrap>", line 969, in _find_and_load
  File "<frozen importlib._bootstrap>", line 958, in _find_and_load_unlocked
  File "<frozen importlib._bootstrap>", line 673, in _load_unlocked
  File "<frozen importlib._bootstrap_external>", line 665, in exec_module
  File "<frozen importlib._bootstrap>", line 222, in _call_with_frames_removed
  File "/home/marclane/Desktop/Targenda/targendaapi/venv/lib/python3.5/site-packages/crispy_forms/templatetags/crispy_forms_tags.py", line 11, in <module>
    from crispy_forms.helper import FormHelper
  File "/home/marclane/Desktop/Targenda/targendaapi/venv/lib/python3.5/site-packages/crispy_forms/helper.py", line 4, in <module>
    from django.core.urlresolvers import reverse, NoReverseMatch
ImportError: No module named 'django.core.urlresolvers'

During handling of the above exception, another exception occurred:

Traceback (most recent call last):
  File "/home/marclane/Desktop/Targenda/targendaapi/venv/lib/python3.5/site-packages/django/core/handlers/exception.py", line 35, in inner
    response = get_response(request)
  File "/home/marclane/Desktop/Targenda/targendaapi/venv/lib/python3.5/site-packages/django/utils/deprecation.py", line 95, in __call__
    response = self.get_response(request)
  File "/home/marclane/Desktop/Targenda/targendaapi/venv/lib/python3.5/site-packages/django/core/handlers/exception.py", line 37, in inner
    response = response_for_exception(request, exc)
  File "/home/marclane/Desktop/Targenda/targendaapi/venv/lib/python3.5/site-packages/django/core/handlers/exception.py", line 87, in response_for_exception
    response = handle_uncaught_exception(request, get_resolver(get_urlconf()), sys.exc_info())
  File "/home/marclane/Desktop/Targenda/targendaapi/venv/lib/python3.5/site-packages/django/core/handlers/exception.py", line 126, in handle_uncaught_exception
    return callback(request, **param_dict)
  File "/home/marclane/Desktop/Targenda/targendaapi/venv/lib/python3.5/site-packages/django/utils/decorators.py", line 142, in _wrapped_view
    response = view_func(request, *args, **kwargs)
  File "/home/marclane/Desktop/Targenda/targendaapi/venv/lib/python3.5/site-packages/django/views/defaults.py", line 69, in server_error
    template = loader.get_template(template_name)
  File "/home/marclane/Desktop/Targenda/targendaapi/venv/lib/python3.5/site-packages/django/template/loader.py", line 12, in get_template
    engines = _engine_list(using)
  File "/home/marclane/Desktop/Targenda/targendaapi/venv/lib/python3.5/site-packages/django/template/loader.py", line 66, in _engine_list
    return engines.all() if using is None else [engines[using]]
  File "/home/marclane/Desktop/Targenda/targendaapi/venv/lib/python3.5/site-packages/django/template/utils.py", line 88, in all
    return [self[alias] for alias in self]
  File "/home/marclane/Desktop/Targenda/targendaapi/venv/lib/python3.5/site-packages/django/template/utils.py", line 88, in <listcomp>
    return [self[alias] for alias in self]
  File "/home/marclane/Desktop/Targenda/targendaapi/venv/lib/python3.5/site-packages/django/template/utils.py", line 79, in __getitem__
    engine = engine_cls(params)
  File "/home/marclane/Desktop/Targenda/targendaapi/venv/lib/python3.5/site-packages/django/template/backends/django.py", line 25, in __init__
    options['libraries'] = self.get_templatetag_libraries(libraries)
  File "/home/marclane/Desktop/Targenda/targendaapi/venv/lib/python3.5/site-packages/django/template/backends/django.py", line 43, in get_templatetag_libraries
    libraries = get_installed_libraries()
  File "/home/marclane/Desktop/Targenda/targendaapi/venv/lib/python3.5/site-packages/django/template/backends/django.py", line 108, in get_installed_libraries
    for name in get_package_libraries(pkg):
  File "/home/marclane/Desktop/Targenda/targendaapi/venv/lib/python3.5/site-packages/django/template/backends/django.py", line 125, in get_package_libraries
    "trying to load '%s': %s" % (entry[1], e)
django.template.library.InvalidTemplateLibrary: Invalid template library specified. ImportError raised when trying to load 'crispy_forms.templatetags.crispy_forms_tags': No module named 'django.core.urlresolvers'
[ERROR] 2018-03-08 18:43:09,315 /home/marclane/Desktop/Targenda/targendaapi/venv/lib/python3.5/site-packages/django/core/handlers/exception.py:74 Invalid HTTP_HOST header: 'localhost:8000'. You may need to add 'localhost' to ALLOWED_HOSTS.
[ERROR] 2018-03-08 18:43:09,321 /home/marclane/Desktop/Targenda/targendaapi/venv/lib/python3.5/site-packages/django/core/handlers/exception.py:118 Internal Server Error: /favicon.ico
Traceback (most recent call last):
  File "/home/marclane/Desktop/Targenda/targendaapi/venv/lib/python3.5/site-packages/django/core/handlers/exception.py", line 35, in inner
    response = get_response(request)
  File "/home/marclane/Desktop/Targenda/targendaapi/venv/lib/python3.5/site-packages/django/utils/deprecation.py", line 93, in __call__
    response = self.process_request(request)
  File "/home/marclane/Desktop/Targenda/targendaapi/venv/lib/python3.5/site-packages/django/middleware/common.py", line 55, in process_request
    host = request.get_host()
  File "/home/marclane/Desktop/Targenda/targendaapi/venv/lib/python3.5/site-packages/django/http/request.py", line 105, in get_host
    raise DisallowedHost(msg)
django.core.exceptions.DisallowedHost: Invalid HTTP_HOST header: 'localhost:8000'. You may need to add 'localhost' to ALLOWED_HOSTS.

During handling of the above exception, another exception occurred:

Traceback (most recent call last):
  File "/home/marclane/Desktop/Targenda/targendaapi/venv/lib/python3.5/site-packages/django/template/utils.py", line 64, in __getitem__
    return self._engines[alias]
KeyError: 'django'

During handling of the above exception, another exception occurred:

Traceback (most recent call last):
  File "/home/marclane/Desktop/Targenda/targendaapi/venv/lib/python3.5/site-packages/django/template/backends/django.py", line 121, in get_package_libraries
    module = import_module(entry[1])
  File "/home/marclane/Desktop/Targenda/targendaapi/venv/lib/python3.5/importlib/__init__.py", line 126, in import_module
    return _bootstrap._gcd_import(name[level:], package, level)
  File "<frozen importlib._bootstrap>", line 986, in _gcd_import
  File "<frozen importlib._bootstrap>", line 969, in _find_and_load
  File "<frozen importlib._bootstrap>", line 958, in _find_and_load_unlocked
  File "<frozen importlib._bootstrap>", line 673, in _load_unlocked
  File "<frozen importlib._bootstrap_external>", line 665, in exec_module
  File "<frozen importlib._bootstrap>", line 222, in _call_with_frames_removed
  File "/home/marclane/Desktop/Targenda/targendaapi/venv/lib/python3.5/site-packages/crispy_forms/templatetags/crispy_forms_tags.py", line 11, in <module>
    from crispy_forms.helper import FormHelper
  File "/home/marclane/Desktop/Targenda/targendaapi/venv/lib/python3.5/site-packages/crispy_forms/helper.py", line 4, in <module>
    from django.core.urlresolvers import reverse, NoReverseMatch
ImportError: No module named 'django.core.urlresolvers'

During handling of the above exception, another exception occurred:

Traceback (most recent call last):
  File "/home/marclane/Desktop/Targenda/targendaapi/venv/lib/python3.5/site-packages/django/core/handlers/exception.py", line 99, in get_exception_response
    response = callback(request, **dict(param_dict, exception=exception))
  File "/home/marclane/Desktop/Targenda/targendaapi/venv/lib/python3.5/site-packages/django/utils/decorators.py", line 142, in _wrapped_view
    response = view_func(request, *args, **kwargs)
  File "/home/marclane/Desktop/Targenda/targendaapi/venv/lib/python3.5/site-packages/django/views/defaults.py", line 87, in bad_request
    template = loader.get_template(template_name)
  File "/home/marclane/Desktop/Targenda/targendaapi/venv/lib/python3.5/site-packages/django/template/loader.py", line 12, in get_template
    engines = _engine_list(using)
  File "/home/marclane/Desktop/Targenda/targendaapi/venv/lib/python3.5/site-packages/django/template/loader.py", line 66, in _engine_list
    return engines.all() if using is None else [engines[using]]
  File "/home/marclane/Desktop/Targenda/targendaapi/venv/lib/python3.5/site-packages/django/template/utils.py", line 88, in all
    return [self[alias] for alias in self]
  File "/home/marclane/Desktop/Targenda/targendaapi/venv/lib/python3.5/site-packages/django/template/utils.py", line 88, in <listcomp>
    return [self[alias] for alias in self]
  File "/home/marclane/Desktop/Targenda/targendaapi/venv/lib/python3.5/site-packages/django/template/utils.py", line 79, in __getitem__
    engine = engine_cls(params)
  File "/home/marclane/Desktop/Targenda/targendaapi/venv/lib/python3.5/site-packages/django/template/backends/django.py", line 25, in __init__
    options['libraries'] = self.get_templatetag_libraries(libraries)
  File "/home/marclane/Desktop/Targenda/targendaapi/venv/lib/python3.5/site-packages/django/template/backends/django.py", line 43, in get_templatetag_libraries
    libraries = get_installed_libraries()
  File "/home/marclane/Desktop/Targenda/targendaapi/venv/lib/python3.5/site-packages/django/template/backends/django.py", line 108, in get_installed_libraries
    for name in get_package_libraries(pkg):
  File "/home/marclane/Desktop/Targenda/targendaapi/venv/lib/python3.5/site-packages/django/template/backends/django.py", line 125, in get_package_libraries
    "trying to load '%s': %s" % (entry[1], e)
django.template.library.InvalidTemplateLibrary: Invalid template library specified. ImportError raised when trying to load 'crispy_forms.templatetags.crispy_forms_tags': No module named 'django.core.urlresolvers'
[ERROR] 2018-03-08 18:43:09,438 /home/marclane/Desktop/Targenda/targendaapi/venv/lib/python3.5/site-packages/django/core/handlers/exception.py:118 Internal Server Error: /favicon.ico
Traceback (most recent call last):
  File "/home/marclane/Desktop/Targenda/targendaapi/venv/lib/python3.5/site-packages/django/core/handlers/exception.py", line 35, in inner
    response = get_response(request)
  File "/home/marclane/Desktop/Targenda/targendaapi/venv/lib/python3.5/site-packages/django/utils/deprecation.py", line 93, in __call__
    response = self.process_request(request)
  File "/home/marclane/Desktop/Targenda/targendaapi/venv/lib/python3.5/site-packages/django/middleware/common.py", line 55, in process_request
    host = request.get_host()
  File "/home/marclane/Desktop/Targenda/targendaapi/venv/lib/python3.5/site-packages/django/http/request.py", line 105, in get_host
    raise DisallowedHost(msg)
django.core.exceptions.DisallowedHost: Invalid HTTP_HOST header: 'localhost:8000'. You may need to add 'localhost' to ALLOWED_HOSTS.

During handling of the above exception, another exception occurred:

Traceback (most recent call last):
  File "/home/marclane/Desktop/Targenda/targendaapi/venv/lib/python3.5/site-packages/django/template/utils.py", line 64, in __getitem__
    return self._engines[alias]
KeyError: 'django'

During handling of the above exception, another exception occurred:

Traceback (most recent call last):
  File "/home/marclane/Desktop/Targenda/targendaapi/venv/lib/python3.5/site-packages/django/template/backends/django.py", line 121, in get_package_libraries
    module = import_module(entry[1])
  File "/home/marclane/Desktop/Targenda/targendaapi/venv/lib/python3.5/importlib/__init__.py", line 126, in import_module
    return _bootstrap._gcd_import(name[level:], package, level)
  File "<frozen importlib._bootstrap>", line 986, in _gcd_import
  File "<frozen importlib._bootstrap>", line 969, in _find_and_load
  File "<frozen importlib._bootstrap>", line 958, in _find_and_load_unlocked
  File "<frozen importlib._bootstrap>", line 673, in _load_unlocked
  File "<frozen importlib._bootstrap_external>", line 665, in exec_module
  File "<frozen importlib._bootstrap>", line 222, in _call_with_frames_removed
  File "/home/marclane/Desktop/Targenda/targendaapi/venv/lib/python3.5/site-packages/crispy_forms/templatetags/crispy_forms_tags.py", line 11, in <module>
    from crispy_forms.helper import FormHelper
  File "/home/marclane/Desktop/Targenda/targendaapi/venv/lib/python3.5/site-packages/crispy_forms/helper.py", line 4, in <module>
    from django.core.urlresolvers import reverse, NoReverseMatch
ImportError: No module named 'django.core.urlresolvers'

During handling of the above exception, another exception occurred:

Traceback (most recent call last):
  File "/home/marclane/Desktop/Targenda/targendaapi/venv/lib/python3.5/site-packages/django/core/handlers/exception.py", line 99, in get_exception_response
    response = callback(request, **dict(param_dict, exception=exception))
  File "/home/marclane/Desktop/Targenda/targendaapi/venv/lib/python3.5/site-packages/django/utils/decorators.py", line 142, in _wrapped_view
    response = view_func(request, *args, **kwargs)
  File "/home/marclane/Desktop/Targenda/targendaapi/venv/lib/python3.5/site-packages/django/views/defaults.py", line 87, in bad_request
    template = loader.get_template(template_name)
  File "/home/marclane/Desktop/Targenda/targendaapi/venv/lib/python3.5/site-packages/django/template/loader.py", line 12, in get_template
    engines = _engine_list(using)
  File "/home/marclane/Desktop/Targenda/targendaapi/venv/lib/python3.5/site-packages/django/template/loader.py", line 66, in _engine_list
    return engines.all() if using is None else [engines[using]]
  File "/home/marclane/Desktop/Targenda/targendaapi/venv/lib/python3.5/site-packages/django/template/utils.py", line 88, in all
    return [self[alias] for alias in self]
  File "/home/marclane/Desktop/Targenda/targendaapi/venv/lib/python3.5/site-packages/django/template/utils.py", line 88, in <listcomp>
    return [self[alias] for alias in self]
  File "/home/marclane/Desktop/Targenda/targendaapi/venv/lib/python3.5/site-packages/django/template/utils.py", line 79, in __getitem__
    engine = engine_cls(params)
  File "/home/marclane/Desktop/Targenda/targendaapi/venv/lib/python3.5/site-packages/django/template/backends/django.py", line 25, in __init__
    options['libraries'] = self.get_templatetag_libraries(libraries)
  File "/home/marclane/Desktop/Targenda/targendaapi/venv/lib/python3.5/site-packages/django/template/backends/django.py", line 43, in get_templatetag_libraries
    libraries = get_installed_libraries()
  File "/home/marclane/Desktop/Targenda/targendaapi/venv/lib/python3.5/site-packages/django/template/backends/django.py", line 108, in get_installed_libraries
    for name in get_package_libraries(pkg):
  File "/home/marclane/Desktop/Targenda/targendaapi/venv/lib/python3.5/site-packages/django/template/backends/django.py", line 125, in get_package_libraries
    "trying to load '%s': %s" % (entry[1], e)
django.template.library.InvalidTemplateLibrary: Invalid template library specified. ImportError raised when trying to load 'crispy_forms.templatetags.crispy_forms_tags': No module named 'django.core.urlresolvers'

During handling of the above exception, another exception occurred:

Traceback (most recent call last):
  File "/home/marclane/Desktop/Targenda/targendaapi/venv/lib/python3.5/site-packages/django/template/utils.py", line 64, in __getitem__
    return self._engines[alias]
KeyError: 'django'

During handling of the above exception, another exception occurred:

Traceback (most recent call last):
  File "/home/marclane/Desktop/Targenda/targendaapi/venv/lib/python3.5/site-packages/django/template/backends/django.py", line 121, in get_package_libraries
    module = import_module(entry[1])
  File "/home/marclane/Desktop/Targenda/targendaapi/venv/lib/python3.5/importlib/__init__.py", line 126, in import_module
    return _bootstrap._gcd_import(name[level:], package, level)
  File "<frozen importlib._bootstrap>", line 986, in _gcd_import
  File "<frozen importlib._bootstrap>", line 969, in _find_and_load
  File "<frozen importlib._bootstrap>", line 958, in _find_and_load_unlocked
  File "<frozen importlib._bootstrap>", line 673, in _load_unlocked
  File "<frozen importlib._bootstrap_external>", line 665, in exec_module
  File "<frozen importlib._bootstrap>", line 222, in _call_with_frames_removed
  File "/home/marclane/Desktop/Targenda/targendaapi/venv/lib/python3.5/site-packages/crispy_forms/templatetags/crispy_forms_tags.py", line 11, in <module>
    from crispy_forms.helper import FormHelper
  File "/home/marclane/Desktop/Targenda/targendaapi/venv/lib/python3.5/site-packages/crispy_forms/helper.py", line 4, in <module>
    from django.core.urlresolvers import reverse, NoReverseMatch
ImportError: No module named 'django.core.urlresolvers'

During handling of the above exception, another exception occurred:

Traceback (most recent call last):
  File "/home/marclane/Desktop/Targenda/targendaapi/venv/lib/python3.5/site-packages/django/core/handlers/exception.py", line 35, in inner
    response = get_response(request)
  File "/home/marclane/Desktop/Targenda/targendaapi/venv/lib/python3.5/site-packages/django/utils/deprecation.py", line 95, in __call__
    response = self.get_response(request)
  File "/home/marclane/Desktop/Targenda/targendaapi/venv/lib/python3.5/site-packages/django/core/handlers/exception.py", line 37, in inner
    response = response_for_exception(request, exc)
  File "/home/marclane/Desktop/Targenda/targendaapi/venv/lib/python3.5/site-packages/django/core/handlers/exception.py", line 79, in response_for_exception
    response = get_exception_response(request, get_resolver(get_urlconf()), 400, exc)
  File "/home/marclane/Desktop/Targenda/targendaapi/venv/lib/python3.5/site-packages/django/core/handlers/exception.py", line 102, in get_exception_response
    response = handle_uncaught_exception(request, resolver, sys.exc_info())
  File "/home/marclane/Desktop/Targenda/targendaapi/venv/lib/python3.5/site-packages/django/core/handlers/exception.py", line 126, in handle_uncaught_exception
    return callback(request, **param_dict)
  File "/home/marclane/Desktop/Targenda/targendaapi/venv/lib/python3.5/site-packages/django/utils/decorators.py", line 142, in _wrapped_view
    response = view_func(request, *args, **kwargs)
  File "/home/marclane/Desktop/Targenda/targendaapi/venv/lib/python3.5/site-packages/django/views/defaults.py", line 69, in server_error
    template = loader.get_template(template_name)
  File "/home/marclane/Desktop/Targenda/targendaapi/venv/lib/python3.5/site-packages/django/template/loader.py", line 12, in get_template
    engines = _engine_list(using)
  File "/home/marclane/Desktop/Targenda/targendaapi/venv/lib/python3.5/site-packages/django/template/loader.py", line 66, in _engine_list
    return engines.all() if using is None else [engines[using]]
  File "/home/marclane/Desktop/Targenda/targendaapi/venv/lib/python3.5/site-packages/django/template/utils.py", line 88, in all
    return [self[alias] for alias in self]
  File "/home/marclane/Desktop/Targenda/targendaapi/venv/lib/python3.5/site-packages/django/template/utils.py", line 88, in <listcomp>
    return [self[alias] for alias in self]
  File "/home/marclane/Desktop/Targenda/targendaapi/venv/lib/python3.5/site-packages/django/template/utils.py", line 79, in __getitem__
    engine = engine_cls(params)
  File "/home/marclane/Desktop/Targenda/targendaapi/venv/lib/python3.5/site-packages/django/template/backends/django.py", line 25, in __init__
    options['libraries'] = self.get_templatetag_libraries(libraries)
  File "/home/marclane/Desktop/Targenda/targendaapi/venv/lib/python3.5/site-packages/django/template/backends/django.py", line 43, in get_templatetag_libraries
    libraries = get_installed_libraries()
  File "/home/marclane/Desktop/Targenda/targendaapi/venv/lib/python3.5/site-packages/django/template/backends/django.py", line 108, in get_installed_libraries
    for name in get_package_libraries(pkg):
  File "/home/marclane/Desktop/Targenda/targendaapi/venv/lib/python3.5/site-packages/django/template/backends/django.py", line 125, in get_package_libraries
    "trying to load '%s': %s" % (entry[1], e)
django.template.library.InvalidTemplateLibrary: Invalid template library specified. ImportError raised when trying to load 'crispy_forms.templatetags.crispy_forms_tags': No module named 'django.core.urlresolvers'
[ERROR] 2018-03-08 18:43:09,561 /home/marclane/Desktop/Targenda/targendaapi/venv/lib/python3.5/site-packages/django/core/handlers/exception.py:118 Internal Server Error: /favicon.ico
Traceback (most recent call last):
  File "/home/marclane/Desktop/Targenda/targendaapi/venv/lib/python3.5/site-packages/django/core/handlers/exception.py", line 35, in inner
    response = get_response(request)
  File "/home/marclane/Desktop/Targenda/targendaapi/venv/lib/python3.5/site-packages/django/utils/deprecation.py", line 93, in __call__
    response = self.process_request(request)
  File "/home/marclane/Desktop/Targenda/targendaapi/venv/lib/python3.5/site-packages/django/middleware/common.py", line 55, in process_request
    host = request.get_host()
  File "/home/marclane/Desktop/Targenda/targendaapi/venv/lib/python3.5/site-packages/django/http/request.py", line 105, in get_host
    raise DisallowedHost(msg)
django.core.exceptions.DisallowedHost: Invalid HTTP_HOST header: 'localhost:8000'. You may need to add 'localhost' to ALLOWED_HOSTS.

During handling of the above exception, another exception occurred:

Traceback (most recent call last):
  File "/home/marclane/Desktop/Targenda/targendaapi/venv/lib/python3.5/site-packages/django/template/utils.py", line 64, in __getitem__
    return self._engines[alias]
KeyError: 'django'

During handling of the above exception, another exception occurred:

Traceback (most recent call last):
  File "/home/marclane/Desktop/Targenda/targendaapi/venv/lib/python3.5/site-packages/django/template/backends/django.py", line 121, in get_package_libraries
    module = import_module(entry[1])
  File "/home/marclane/Desktop/Targenda/targendaapi/venv/lib/python3.5/importlib/__init__.py", line 126, in import_module
    return _bootstrap._gcd_import(name[level:], package, level)
  File "<frozen importlib._bootstrap>", line 986, in _gcd_import
  File "<frozen importlib._bootstrap>", line 969, in _find_and_load
  File "<frozen importlib._bootstrap>", line 958, in _find_and_load_unlocked
  File "<frozen importlib._bootstrap>", line 673, in _load_unlocked
  File "<frozen importlib._bootstrap_external>", line 665, in exec_module
  File "<frozen importlib._bootstrap>", line 222, in _call_with_frames_removed
  File "/home/marclane/Desktop/Targenda/targendaapi/venv/lib/python3.5/site-packages/crispy_forms/templatetags/crispy_forms_tags.py", line 11, in <module>
    from crispy_forms.helper import FormHelper
  File "/home/marclane/Desktop/Targenda/targendaapi/venv/lib/python3.5/site-packages/crispy_forms/helper.py", line 4, in <module>
    from django.core.urlresolvers import reverse, NoReverseMatch
ImportError: No module named 'django.core.urlresolvers'

During handling of the above exception, another exception occurred:

Traceback (most recent call last):
  File "/home/marclane/Desktop/Targenda/targendaapi/venv/lib/python3.5/site-packages/django/core/handlers/exception.py", line 99, in get_exception_response
    response = callback(request, **dict(param_dict, exception=exception))
  File "/home/marclane/Desktop/Targenda/targendaapi/venv/lib/python3.5/site-packages/django/utils/decorators.py", line 142, in _wrapped_view
    response = view_func(request, *args, **kwargs)
  File "/home/marclane/Desktop/Targenda/targendaapi/venv/lib/python3.5/site-packages/django/views/defaults.py", line 87, in bad_request
    template = loader.get_template(template_name)
  File "/home/marclane/Desktop/Targenda/targendaapi/venv/lib/python3.5/site-packages/django/template/loader.py", line 12, in get_template
    engines = _engine_list(using)
  File "/home/marclane/Desktop/Targenda/targendaapi/venv/lib/python3.5/site-packages/django/template/loader.py", line 66, in _engine_list
    return engines.all() if using is None else [engines[using]]
  File "/home/marclane/Desktop/Targenda/targendaapi/venv/lib/python3.5/site-packages/django/template/utils.py", line 88, in all
    return [self[alias] for alias in self]
  File "/home/marclane/Desktop/Targenda/targendaapi/venv/lib/python3.5/site-packages/django/template/utils.py", line 88, in <listcomp>
    return [self[alias] for alias in self]
  File "/home/marclane/Desktop/Targenda/targendaapi/venv/lib/python3.5/site-packages/django/template/utils.py", line 79, in __getitem__
    engine = engine_cls(params)
  File "/home/marclane/Desktop/Targenda/targendaapi/venv/lib/python3.5/site-packages/django/template/backends/django.py", line 25, in __init__
    options['libraries'] = self.get_templatetag_libraries(libraries)
  File "/home/marclane/Desktop/Targenda/targendaapi/venv/lib/python3.5/site-packages/django/template/backends/django.py", line 43, in get_templatetag_libraries
    libraries = get_installed_libraries()
  File "/home/marclane/Desktop/Targenda/targendaapi/venv/lib/python3.5/site-packages/django/template/backends/django.py", line 108, in get_installed_libraries
    for name in get_package_libraries(pkg):
  File "/home/marclane/Desktop/Targenda/targendaapi/venv/lib/python3.5/site-packages/django/template/backends/django.py", line 125, in get_package_libraries
    "trying to load '%s': %s" % (entry[1], e)
django.template.library.InvalidTemplateLibrary: Invalid template library specified. ImportError raised when trying to load 'crispy_forms.templatetags.crispy_forms_tags': No module named 'django.core.urlresolvers'

During handling of the above exception, another exception occurred:

Traceback (most recent call last):
  File "/home/marclane/Desktop/Targenda/targendaapi/venv/lib/python3.5/site-packages/django/template/utils.py", line 64, in __getitem__
    return self._engines[alias]
KeyError: 'django'

During handling of the above exception, another exception occurred:

Traceback (most recent call last):
  File "/home/marclane/Desktop/Targenda/targendaapi/venv/lib/python3.5/site-packages/django/template/backends/django.py", line 121, in get_package_libraries
    module = import_module(entry[1])
  File "/home/marclane/Desktop/Targenda/targendaapi/venv/lib/python3.5/importlib/__init__.py", line 126, in import_module
    return _bootstrap._gcd_import(name[level:], package, level)
  File "<frozen importlib._bootstrap>", line 986, in _gcd_import
  File "<frozen importlib._bootstrap>", line 969, in _find_and_load
  File "<frozen importlib._bootstrap>", line 958, in _find_and_load_unlocked
  File "<frozen importlib._bootstrap>", line 673, in _load_unlocked
  File "<frozen importlib._bootstrap_external>", line 665, in exec_module
  File "<frozen importlib._bootstrap>", line 222, in _call_with_frames_removed
  File "/home/marclane/Desktop/Targenda/targendaapi/venv/lib/python3.5/site-packages/crispy_forms/templatetags/crispy_forms_tags.py", line 11, in <module>
    from crispy_forms.helper import FormHelper
  File "/home/marclane/Desktop/Targenda/targendaapi/venv/lib/python3.5/site-packages/crispy_forms/helper.py", line 4, in <module>
    from django.core.urlresolvers import reverse, NoReverseMatch
ImportError: No module named 'django.core.urlresolvers'

During handling of the above exception, another exception occurred:

Traceback (most recent call last):
  File "/home/marclane/Desktop/Targenda/targendaapi/venv/lib/python3.5/site-packages/django/core/handlers/exception.py", line 35, in inner
    response = get_response(request)
  File "/home/marclane/Desktop/Targenda/targendaapi/venv/lib/python3.5/site-packages/django/utils/deprecation.py", line 95, in __call__
    response = self.get_response(request)
  File "/home/marclane/Desktop/Targenda/targendaapi/venv/lib/python3.5/site-packages/django/core/handlers/exception.py", line 37, in inner
    response = response_for_exception(request, exc)
  File "/home/marclane/Desktop/Targenda/targendaapi/venv/lib/python3.5/site-packages/django/core/handlers/exception.py", line 79, in response_for_exception
    response = get_exception_response(request, get_resolver(get_urlconf()), 400, exc)
  File "/home/marclane/Desktop/Targenda/targendaapi/venv/lib/python3.5/site-packages/django/core/handlers/exception.py", line 102, in get_exception_response
    response = handle_uncaught_exception(request, resolver, sys.exc_info())
  File "/home/marclane/Desktop/Targenda/targendaapi/venv/lib/python3.5/site-packages/django/core/handlers/exception.py", line 126, in handle_uncaught_exception
    return callback(request, **param_dict)
  File "/home/marclane/Desktop/Targenda/targendaapi/venv/lib/python3.5/site-packages/django/utils/decorators.py", line 142, in _wrapped_view
    response = view_func(request, *args, **kwargs)
  File "/home/marclane/Desktop/Targenda/targendaapi/venv/lib/python3.5/site-packages/django/views/defaults.py", line 69, in server_error
    template = loader.get_template(template_name)
  File "/home/marclane/Desktop/Targenda/targendaapi/venv/lib/python3.5/site-packages/django/template/loader.py", line 12, in get_template
    engines = _engine_list(using)
  File "/home/marclane/Desktop/Targenda/targendaapi/venv/lib/python3.5/site-packages/django/template/loader.py", line 66, in _engine_list
    return engines.all() if using is None else [engines[using]]
  File "/home/marclane/Desktop/Targenda/targendaapi/venv/lib/python3.5/site-packages/django/template/utils.py", line 88, in all
    return [self[alias] for alias in self]
  File "/home/marclane/Desktop/Targenda/targendaapi/venv/lib/python3.5/site-packages/django/template/utils.py", line 88, in <listcomp>
    return [self[alias] for alias in self]
  File "/home/marclane/Desktop/Targenda/targendaapi/venv/lib/python3.5/site-packages/django/template/utils.py", line 79, in __getitem__
    engine = engine_cls(params)
  File "/home/marclane/Desktop/Targenda/targendaapi/venv/lib/python3.5/site-packages/django/template/backends/django.py", line 25, in __init__
    options['libraries'] = self.get_templatetag_libraries(libraries)
  File "/home/marclane/Desktop/Targenda/targendaapi/venv/lib/python3.5/site-packages/django/template/backends/django.py", line 43, in get_templatetag_libraries
    libraries = get_installed_libraries()
  File "/home/marclane/Desktop/Targenda/targendaapi/venv/lib/python3.5/site-packages/django/template/backends/django.py", line 108, in get_installed_libraries
    for name in get_package_libraries(pkg):
  File "/home/marclane/Desktop/Targenda/targendaapi/venv/lib/python3.5/site-packages/django/template/backends/django.py", line 125, in get_package_libraries
    "trying to load '%s': %s" % (entry[1], e)
django.template.library.InvalidTemplateLibrary: Invalid template library specified. ImportError raised when trying to load 'crispy_forms.templatetags.crispy_forms_tags': No module named 'django.core.urlresolvers'

During handling of the above exception, another exception occurred:

Traceback (most recent call last):
  File "/home/marclane/Desktop/Targenda/targendaapi/venv/lib/python3.5/site-packages/django/template/utils.py", line 64, in __getitem__
    return self._engines[alias]
KeyError: 'django'

During handling of the above exception, another exception occurred:

Traceback (most recent call last):
  File "/home/marclane/Desktop/Targenda/targendaapi/venv/lib/python3.5/site-packages/django/template/backends/django.py", line 121, in get_package_libraries
    module = import_module(entry[1])
  File "/home/marclane/Desktop/Targenda/targendaapi/venv/lib/python3.5/importlib/__init__.py", line 126, in import_module
    return _bootstrap._gcd_import(name[level:], package, level)
  File "<frozen importlib._bootstrap>", line 986, in _gcd_import
  File "<frozen importlib._bootstrap>", line 969, in _find_and_load
  File "<frozen importlib._bootstrap>", line 958, in _find_and_load_unlocked
  File "<frozen importlib._bootstrap>", line 673, in _load_unlocked
  File "<frozen importlib._bootstrap_external>", line 665, in exec_module
  File "<frozen importlib._bootstrap>", line 222, in _call_with_frames_removed
  File "/home/marclane/Desktop/Targenda/targendaapi/venv/lib/python3.5/site-packages/crispy_forms/templatetags/crispy_forms_tags.py", line 11, in <module>
    from crispy_forms.helper import FormHelper
  File "/home/marclane/Desktop/Targenda/targendaapi/venv/lib/python3.5/site-packages/crispy_forms/helper.py", line 4, in <module>
    from django.core.urlresolvers import reverse, NoReverseMatch
ImportError: No module named 'django.core.urlresolvers'

During handling of the above exception, another exception occurred:

Traceback (most recent call last):
  File "/home/marclane/Desktop/Targenda/targendaapi/venv/lib/python3.5/site-packages/django/core/handlers/exception.py", line 35, in inner
    response = get_response(request)
  File "/home/marclane/Desktop/Targenda/targendaapi/venv/lib/python3.5/site-packages/django/utils/deprecation.py", line 95, in __call__
    response = self.get_response(request)
  File "/home/marclane/Desktop/Targenda/targendaapi/venv/lib/python3.5/site-packages/django/core/handlers/exception.py", line 37, in inner
    response = response_for_exception(request, exc)
  File "/home/marclane/Desktop/Targenda/targendaapi/venv/lib/python3.5/site-packages/django/core/handlers/exception.py", line 87, in response_for_exception
    response = handle_uncaught_exception(request, get_resolver(get_urlconf()), sys.exc_info())
  File "/home/marclane/Desktop/Targenda/targendaapi/venv/lib/python3.5/site-packages/django/core/handlers/exception.py", line 126, in handle_uncaught_exception
    return callback(request, **param_dict)
  File "/home/marclane/Desktop/Targenda/targendaapi/venv/lib/python3.5/site-packages/django/utils/decorators.py", line 142, in _wrapped_view
    response = view_func(request, *args, **kwargs)
  File "/home/marclane/Desktop/Targenda/targendaapi/venv/lib/python3.5/site-packages/django/views/defaults.py", line 69, in server_error
    template = loader.get_template(template_name)
  File "/home/marclane/Desktop/Targenda/targendaapi/venv/lib/python3.5/site-packages/django/template/loader.py", line 12, in get_template
    engines = _engine_list(using)
  File "/home/marclane/Desktop/Targenda/targendaapi/venv/lib/python3.5/site-packages/django/template/loader.py", line 66, in _engine_list
    return engines.all() if using is None else [engines[using]]
  File "/home/marclane/Desktop/Targenda/targendaapi/venv/lib/python3.5/site-packages/django/template/utils.py", line 88, in all
    return [self[alias] for alias in self]
  File "/home/marclane/Desktop/Targenda/targendaapi/venv/lib/python3.5/site-packages/django/template/utils.py", line 88, in <listcomp>
    return [self[alias] for alias in self]
  File "/home/marclane/Desktop/Targenda/targendaapi/venv/lib/python3.5/site-packages/django/template/utils.py", line 79, in __getitem__
    engine = engine_cls(params)
  File "/home/marclane/Desktop/Targenda/targendaapi/venv/lib/python3.5/site-packages/django/template/backends/django.py", line 25, in __init__
    options['libraries'] = self.get_templatetag_libraries(libraries)
  File "/home/marclane/Desktop/Targenda/targendaapi/venv/lib/python3.5/site-packages/django/template/backends/django.py", line 43, in get_templatetag_libraries
    libraries = get_installed_libraries()
  File "/home/marclane/Desktop/Targenda/targendaapi/venv/lib/python3.5/site-packages/django/template/backends/django.py", line 108, in get_installed_libraries
    for name in get_package_libraries(pkg):
  File "/home/marclane/Desktop/Targenda/targendaapi/venv/lib/python3.5/site-packages/django/template/backends/django.py", line 125, in get_package_libraries
    "trying to load '%s': %s" % (entry[1], e)
django.template.library.InvalidTemplateLibrary: Invalid template library specified. ImportError raised when trying to load 'crispy_forms.templatetags.crispy_forms_tags': No module named 'django.core.urlresolvers'
[ERROR] 2018-03-08 18:43:09,750 /home/marclane/Desktop/Targenda/targendaapi/venv/lib/python3.5/site-packages/django/core/handlers/exception.py:74 Invalid HTTP_HOST header: 'localhost:8000'. You may need to add 'localhost' to ALLOWED_HOSTS.
[ERROR] 2018-03-08 18:43:09,754 /home/marclane/Desktop/Targenda/targendaapi/venv/lib/python3.5/site-packages/django/core/handlers/exception.py:118 Internal Server Error: /favicon.ico
Traceback (most recent call last):
  File "/home/marclane/Desktop/Targenda/targendaapi/venv/lib/python3.5/site-packages/django/core/handlers/exception.py", line 35, in inner
    response = get_response(request)
  File "/home/marclane/Desktop/Targenda/targendaapi/venv/lib/python3.5/site-packages/django/utils/deprecation.py", line 93, in __call__
    response = self.process_request(request)
  File "/home/marclane/Desktop/Targenda/targendaapi/venv/lib/python3.5/site-packages/django/middleware/common.py", line 55, in process_request
    host = request.get_host()
  File "/home/marclane/Desktop/Targenda/targendaapi/venv/lib/python3.5/site-packages/django/http/request.py", line 105, in get_host
    raise DisallowedHost(msg)
django.core.exceptions.DisallowedHost: Invalid HTTP_HOST header: 'localhost:8000'. You may need to add 'localhost' to ALLOWED_HOSTS.

During handling of the above exception, another exception occurred:

Traceback (most recent call last):
  File "/home/marclane/Desktop/Targenda/targendaapi/venv/lib/python3.5/site-packages/django/template/utils.py", line 64, in __getitem__
    return self._engines[alias]
KeyError: 'django'

During handling of the above exception, another exception occurred:

Traceback (most recent call last):
  File "/home/marclane/Desktop/Targenda/targendaapi/venv/lib/python3.5/site-packages/django/template/backends/django.py", line 121, in get_package_libraries
    module = import_module(entry[1])
  File "/home/marclane/Desktop/Targenda/targendaapi/venv/lib/python3.5/importlib/__init__.py", line 126, in import_module
    return _bootstrap._gcd_import(name[level:], package, level)
  File "<frozen importlib._bootstrap>", line 986, in _gcd_import
  File "<frozen importlib._bootstrap>", line 969, in _find_and_load
  File "<frozen importlib._bootstrap>", line 958, in _find_and_load_unlocked
  File "<frozen importlib._bootstrap>", line 673, in _load_unlocked
  File "<frozen importlib._bootstrap_external>", line 665, in exec_module
  File "<frozen importlib._bootstrap>", line 222, in _call_with_frames_removed
  File "/home/marclane/Desktop/Targenda/targendaapi/venv/lib/python3.5/site-packages/crispy_forms/templatetags/crispy_forms_tags.py", line 11, in <module>
    from crispy_forms.helper import FormHelper
  File "/home/marclane/Desktop/Targenda/targendaapi/venv/lib/python3.5/site-packages/crispy_forms/helper.py", line 4, in <module>
    from django.core.urlresolvers import reverse, NoReverseMatch
ImportError: No module named 'django.core.urlresolvers'

During handling of the above exception, another exception occurred:

Traceback (most recent call last):
  File "/home/marclane/Desktop/Targenda/targendaapi/venv/lib/python3.5/site-packages/django/core/handlers/exception.py", line 99, in get_exception_response
    response = callback(request, **dict(param_dict, exception=exception))
  File "/home/marclane/Desktop/Targenda/targendaapi/venv/lib/python3.5/site-packages/django/utils/decorators.py", line 142, in _wrapped_view
    response = view_func(request, *args, **kwargs)
  File "/home/marclane/Desktop/Targenda/targendaapi/venv/lib/python3.5/site-packages/django/views/defaults.py", line 87, in bad_request
    template = loader.get_template(template_name)
  File "/home/marclane/Desktop/Targenda/targendaapi/venv/lib/python3.5/site-packages/django/template/loader.py", line 12, in get_template
    engines = _engine_list(using)
  File "/home/marclane/Desktop/Targenda/targendaapi/venv/lib/python3.5/site-packages/django/template/loader.py", line 66, in _engine_list
    return engines.all() if using is None else [engines[using]]
  File "/home/marclane/Desktop/Targenda/targendaapi/venv/lib/python3.5/site-packages/django/template/utils.py", line 88, in all
    return [self[alias] for alias in self]
  File "/home/marclane/Desktop/Targenda/targendaapi/venv/lib/python3.5/site-packages/django/template/utils.py", line 88, in <listcomp>
    return [self[alias] for alias in self]
  File "/home/marclane/Desktop/Targenda/targendaapi/venv/lib/python3.5/site-packages/django/template/utils.py", line 79, in __getitem__
    engine = engine_cls(params)
  File "/home/marclane/Desktop/Targenda/targendaapi/venv/lib/python3.5/site-packages/django/template/backends/django.py", line 25, in __init__
    options['libraries'] = self.get_templatetag_libraries(libraries)
  File "/home/marclane/Desktop/Targenda/targendaapi/venv/lib/python3.5/site-packages/django/template/backends/django.py", line 43, in get_templatetag_libraries
    libraries = get_installed_libraries()
  File "/home/marclane/Desktop/Targenda/targendaapi/venv/lib/python3.5/site-packages/django/template/backends/django.py", line 108, in get_installed_libraries
    for name in get_package_libraries(pkg):
  File "/home/marclane/Desktop/Targenda/targendaapi/venv/lib/python3.5/site-packages/django/template/backends/django.py", line 125, in get_package_libraries
    "trying to load '%s': %s" % (entry[1], e)
django.template.library.InvalidTemplateLibrary: Invalid template library specified. ImportError raised when trying to load 'crispy_forms.templatetags.crispy_forms_tags': No module named 'django.core.urlresolvers'
[ERROR] 2018-03-08 18:43:09,852 /home/marclane/Desktop/Targenda/targendaapi/venv/lib/python3.5/site-packages/django/core/handlers/exception.py:118 Internal Server Error: /favicon.ico
Traceback (most recent call last):
  File "/home/marclane/Desktop/Targenda/targendaapi/venv/lib/python3.5/site-packages/django/core/handlers/exception.py", line 35, in inner
    response = get_response(request)
  File "/home/marclane/Desktop/Targenda/targendaapi/venv/lib/python3.5/site-packages/django/utils/deprecation.py", line 93, in __call__
    response = self.process_request(request)
  File "/home/marclane/Desktop/Targenda/targendaapi/venv/lib/python3.5/site-packages/django/middleware/common.py", line 55, in process_request
    host = request.get_host()
  File "/home/marclane/Desktop/Targenda/targendaapi/venv/lib/python3.5/site-packages/django/http/request.py", line 105, in get_host
    raise DisallowedHost(msg)
django.core.exceptions.DisallowedHost: Invalid HTTP_HOST header: 'localhost:8000'. You may need to add 'localhost' to ALLOWED_HOSTS.

During handling of the above exception, another exception occurred:

Traceback (most recent call last):
  File "/home/marclane/Desktop/Targenda/targendaapi/venv/lib/python3.5/site-packages/django/template/utils.py", line 64, in __getitem__
    return self._engines[alias]
KeyError: 'django'

During handling of the above exception, another exception occurred:

Traceback (most recent call last):
  File "/home/marclane/Desktop/Targenda/targendaapi/venv/lib/python3.5/site-packages/django/template/backends/django.py", line 121, in get_package_libraries
    module = import_module(entry[1])
  File "/home/marclane/Desktop/Targenda/targendaapi/venv/lib/python3.5/importlib/__init__.py", line 126, in import_module
    return _bootstrap._gcd_import(name[level:], package, level)
  File "<frozen importlib._bootstrap>", line 986, in _gcd_import
  File "<frozen importlib._bootstrap>", line 969, in _find_and_load
  File "<frozen importlib._bootstrap>", line 958, in _find_and_load_unlocked
  File "<frozen importlib._bootstrap>", line 673, in _load_unlocked
  File "<frozen importlib._bootstrap_external>", line 665, in exec_module
  File "<frozen importlib._bootstrap>", line 222, in _call_with_frames_removed
  File "/home/marclane/Desktop/Targenda/targendaapi/venv/lib/python3.5/site-packages/crispy_forms/templatetags/crispy_forms_tags.py", line 11, in <module>
    from crispy_forms.helper import FormHelper
  File "/home/marclane/Desktop/Targenda/targendaapi/venv/lib/python3.5/site-packages/crispy_forms/helper.py", line 4, in <module>
    from django.core.urlresolvers import reverse, NoReverseMatch
ImportError: No module named 'django.core.urlresolvers'

During handling of the above exception, another exception occurred:

Traceback (most recent call last):
  File "/home/marclane/Desktop/Targenda/targendaapi/venv/lib/python3.5/site-packages/django/core/handlers/exception.py", line 99, in get_exception_response
    response = callback(request, **dict(param_dict, exception=exception))
  File "/home/marclane/Desktop/Targenda/targendaapi/venv/lib/python3.5/site-packages/django/utils/decorators.py", line 142, in _wrapped_view
    response = view_func(request, *args, **kwargs)
  File "/home/marclane/Desktop/Targenda/targendaapi/venv/lib/python3.5/site-packages/django/views/defaults.py", line 87, in bad_request
    template = loader.get_template(template_name)
  File "/home/marclane/Desktop/Targenda/targendaapi/venv/lib/python3.5/site-packages/django/template/loader.py", line 12, in get_template
    engines = _engine_list(using)
  File "/home/marclane/Desktop/Targenda/targendaapi/venv/lib/python3.5/site-packages/django/template/loader.py", line 66, in _engine_list
    return engines.all() if using is None else [engines[using]]
  File "/home/marclane/Desktop/Targenda/targendaapi/venv/lib/python3.5/site-packages/django/template/utils.py", line 88, in all
    return [self[alias] for alias in self]
  File "/home/marclane/Desktop/Targenda/targendaapi/venv/lib/python3.5/site-packages/django/template/utils.py", line 88, in <listcomp>
    return [self[alias] for alias in self]
  File "/home/marclane/Desktop/Targenda/targendaapi/venv/lib/python3.5/site-packages/django/template/utils.py", line 79, in __getitem__
    engine = engine_cls(params)
  File "/home/marclane/Desktop/Targenda/targendaapi/venv/lib/python3.5/site-packages/django/template/backends/django.py", line 25, in __init__
    options['libraries'] = self.get_templatetag_libraries(libraries)
  File "/home/marclane/Desktop/Targenda/targendaapi/venv/lib/python3.5/site-packages/django/template/backends/django.py", line 43, in get_templatetag_libraries
    libraries = get_installed_libraries()
  File "/home/marclane/Desktop/Targenda/targendaapi/venv/lib/python3.5/site-packages/django/template/backends/django.py", line 108, in get_installed_libraries
    for name in get_package_libraries(pkg):
  File "/home/marclane/Desktop/Targenda/targendaapi/venv/lib/python3.5/site-packages/django/template/backends/django.py", line 125, in get_package_libraries
    "trying to load '%s': %s" % (entry[1], e)
django.template.library.InvalidTemplateLibrary: Invalid template library specified. ImportError raised when trying to load 'crispy_forms.templatetags.crispy_forms_tags': No module named 'django.core.urlresolvers'

During handling of the above exception, another exception occurred:

Traceback (most recent call last):
  File "/home/marclane/Desktop/Targenda/targendaapi/venv/lib/python3.5/site-packages/django/template/utils.py", line 64, in __getitem__
    return self._engines[alias]
KeyError: 'django'

During handling of the above exception, another exception occurred:

Traceback (most recent call last):
  File "/home/marclane/Desktop/Targenda/targendaapi/venv/lib/python3.5/site-packages/django/template/backends/django.py", line 121, in get_package_libraries
    module = import_module(entry[1])
  File "/home/marclane/Desktop/Targenda/targendaapi/venv/lib/python3.5/importlib/__init__.py", line 126, in import_module
    return _bootstrap._gcd_import(name[level:], package, level)
  File "<frozen importlib._bootstrap>", line 986, in _gcd_import
  File "<frozen importlib._bootstrap>", line 969, in _find_and_load
  File "<frozen importlib._bootstrap>", line 958, in _find_and_load_unlocked
  File "<frozen importlib._bootstrap>", line 673, in _load_unlocked
  File "<frozen importlib._bootstrap_external>", line 665, in exec_module
  File "<frozen importlib._bootstrap>", line 222, in _call_with_frames_removed
  File "/home/marclane/Desktop/Targenda/targendaapi/venv/lib/python3.5/site-packages/crispy_forms/templatetags/crispy_forms_tags.py", line 11, in <module>
    from crispy_forms.helper import FormHelper
  File "/home/marclane/Desktop/Targenda/targendaapi/venv/lib/python3.5/site-packages/crispy_forms/helper.py", line 4, in <module>
    from django.core.urlresolvers import reverse, NoReverseMatch
ImportError: No module named 'django.core.urlresolvers'

During handling of the above exception, another exception occurred:

Traceback (most recent call last):
  File "/home/marclane/Desktop/Targenda/targendaapi/venv/lib/python3.5/site-packages/django/core/handlers/exception.py", line 35, in inner
    response = get_response(request)
  File "/home/marclane/Desktop/Targenda/targendaapi/venv/lib/python3.5/site-packages/django/utils/deprecation.py", line 95, in __call__
    response = self.get_response(request)
  File "/home/marclane/Desktop/Targenda/targendaapi/venv/lib/python3.5/site-packages/django/core/handlers/exception.py", line 37, in inner
    response = response_for_exception(request, exc)
  File "/home/marclane/Desktop/Targenda/targendaapi/venv/lib/python3.5/site-packages/django/core/handlers/exception.py", line 79, in response_for_exception
    response = get_exception_response(request, get_resolver(get_urlconf()), 400, exc)
  File "/home/marclane/Desktop/Targenda/targendaapi/venv/lib/python3.5/site-packages/django/core/handlers/exception.py", line 102, in get_exception_response
    response = handle_uncaught_exception(request, resolver, sys.exc_info())
  File "/home/marclane/Desktop/Targenda/targendaapi/venv/lib/python3.5/site-packages/django/core/handlers/exception.py", line 126, in handle_uncaught_exception
    return callback(request, **param_dict)
  File "/home/marclane/Desktop/Targenda/targendaapi/venv/lib/python3.5/site-packages/django/utils/decorators.py", line 142, in _wrapped_view
    response = view_func(request, *args, **kwargs)
  File "/home/marclane/Desktop/Targenda/targendaapi/venv/lib/python3.5/site-packages/django/views/defaults.py", line 69, in server_error
    template = loader.get_template(template_name)
  File "/home/marclane/Desktop/Targenda/targendaapi/venv/lib/python3.5/site-packages/django/template/loader.py", line 12, in get_template
    engines = _engine_list(using)
  File "/home/marclane/Desktop/Targenda/targendaapi/venv/lib/python3.5/site-packages/django/template/loader.py", line 66, in _engine_list
    return engines.all() if using is None else [engines[using]]
  File "/home/marclane/Desktop/Targenda/targendaapi/venv/lib/python3.5/site-packages/django/template/utils.py", line 88, in all
    return [self[alias] for alias in self]
  File "/home/marclane/Desktop/Targenda/targendaapi/venv/lib/python3.5/site-packages/django/template/utils.py", line 88, in <listcomp>
    return [self[alias] for alias in self]
  File "/home/marclane/Desktop/Targenda/targendaapi/venv/lib/python3.5/site-packages/django/template/utils.py", line 79, in __getitem__
    engine = engine_cls(params)
  File "/home/marclane/Desktop/Targenda/targendaapi/venv/lib/python3.5/site-packages/django/template/backends/django.py", line 25, in __init__
    options['libraries'] = self.get_templatetag_libraries(libraries)
  File "/home/marclane/Desktop/Targenda/targendaapi/venv/lib/python3.5/site-packages/django/template/backends/django.py", line 43, in get_templatetag_libraries
    libraries = get_installed_libraries()
  File "/home/marclane/Desktop/Targenda/targendaapi/venv/lib/python3.5/site-packages/django/template/backends/django.py", line 108, in get_installed_libraries
    for name in get_package_libraries(pkg):
  File "/home/marclane/Desktop/Targenda/targendaapi/venv/lib/python3.5/site-packages/django/template/backends/django.py", line 125, in get_package_libraries
    "trying to load '%s': %s" % (entry[1], e)
django.template.library.InvalidTemplateLibrary: Invalid template library specified. ImportError raised when trying to load 'crispy_forms.templatetags.crispy_forms_tags': No module named 'django.core.urlresolvers'
[ERROR] 2018-03-08 18:43:09,978 /home/marclane/Desktop/Targenda/targendaapi/venv/lib/python3.5/site-packages/django/core/handlers/exception.py:118 Internal Server Error: /favicon.ico
Traceback (most recent call last):
  File "/home/marclane/Desktop/Targenda/targendaapi/venv/lib/python3.5/site-packages/django/core/handlers/exception.py", line 35, in inner
    response = get_response(request)
  File "/home/marclane/Desktop/Targenda/targendaapi/venv/lib/python3.5/site-packages/django/utils/deprecation.py", line 93, in __call__
    response = self.process_request(request)
  File "/home/marclane/Desktop/Targenda/targendaapi/venv/lib/python3.5/site-packages/django/middleware/common.py", line 55, in process_request
    host = request.get_host()
  File "/home/marclane/Desktop/Targenda/targendaapi/venv/lib/python3.5/site-packages/django/http/request.py", line 105, in get_host
    raise DisallowedHost(msg)
django.core.exceptions.DisallowedHost: Invalid HTTP_HOST header: 'localhost:8000'. You may need to add 'localhost' to ALLOWED_HOSTS.

During handling of the above exception, another exception occurred:

Traceback (most recent call last):
  File "/home/marclane/Desktop/Targenda/targendaapi/venv/lib/python3.5/site-packages/django/template/utils.py", line 64, in __getitem__
    return self._engines[alias]
KeyError: 'django'

During handling of the above exception, another exception occurred:

Traceback (most recent call last):
  File "/home/marclane/Desktop/Targenda/targendaapi/venv/lib/python3.5/site-packages/django/template/backends/django.py", line 121, in get_package_libraries
    module = import_module(entry[1])
  File "/home/marclane/Desktop/Targenda/targendaapi/venv/lib/python3.5/importlib/__init__.py", line 126, in import_module
    return _bootstrap._gcd_import(name[level:], package, level)
  File "<frozen importlib._bootstrap>", line 986, in _gcd_import
  File "<frozen importlib._bootstrap>", line 969, in _find_and_load
  File "<frozen importlib._bootstrap>", line 958, in _find_and_load_unlocked
  File "<frozen importlib._bootstrap>", line 673, in _load_unlocked
  File "<frozen importlib._bootstrap_external>", line 665, in exec_module
  File "<frozen importlib._bootstrap>", line 222, in _call_with_frames_removed
  File "/home/marclane/Desktop/Targenda/targendaapi/venv/lib/python3.5/site-packages/crispy_forms/templatetags/crispy_forms_tags.py", line 11, in <module>
    from crispy_forms.helper import FormHelper
  File "/home/marclane/Desktop/Targenda/targendaapi/venv/lib/python3.5/site-packages/crispy_forms/helper.py", line 4, in <module>
    from django.core.urlresolvers import reverse, NoReverseMatch
ImportError: No module named 'django.core.urlresolvers'

During handling of the above exception, another exception occurred:

Traceback (most recent call last):
  File "/home/marclane/Desktop/Targenda/targendaapi/venv/lib/python3.5/site-packages/django/core/handlers/exception.py", line 99, in get_exception_response
    response = callback(request, **dict(param_dict, exception=exception))
  File "/home/marclane/Desktop/Targenda/targendaapi/venv/lib/python3.5/site-packages/django/utils/decorators.py", line 142, in _wrapped_view
    response = view_func(request, *args, **kwargs)
  File "/home/marclane/Desktop/Targenda/targendaapi/venv/lib/python3.5/site-packages/django/views/defaults.py", line 87, in bad_request
    template = loader.get_template(template_name)
  File "/home/marclane/Desktop/Targenda/targendaapi/venv/lib/python3.5/site-packages/django/template/loader.py", line 12, in get_template
    engines = _engine_list(using)
  File "/home/marclane/Desktop/Targenda/targendaapi/venv/lib/python3.5/site-packages/django/template/loader.py", line 66, in _engine_list
    return engines.all() if using is None else [engines[using]]
  File "/home/marclane/Desktop/Targenda/targendaapi/venv/lib/python3.5/site-packages/django/template/utils.py", line 88, in all
    return [self[alias] for alias in self]
  File "/home/marclane/Desktop/Targenda/targendaapi/venv/lib/python3.5/site-packages/django/template/utils.py", line 88, in <listcomp>
    return [self[alias] for alias in self]
  File "/home/marclane/Desktop/Targenda/targendaapi/venv/lib/python3.5/site-packages/django/template/utils.py", line 79, in __getitem__
    engine = engine_cls(params)
  File "/home/marclane/Desktop/Targenda/targendaapi/venv/lib/python3.5/site-packages/django/template/backends/django.py", line 25, in __init__
    options['libraries'] = self.get_templatetag_libraries(libraries)
  File "/home/marclane/Desktop/Targenda/targendaapi/venv/lib/python3.5/site-packages/django/template/backends/django.py", line 43, in get_templatetag_libraries
    libraries = get_installed_libraries()
  File "/home/marclane/Desktop/Targenda/targendaapi/venv/lib/python3.5/site-packages/django/template/backends/django.py", line 108, in get_installed_libraries
    for name in get_package_libraries(pkg):
  File "/home/marclane/Desktop/Targenda/targendaapi/venv/lib/python3.5/site-packages/django/template/backends/django.py", line 125, in get_package_libraries
    "trying to load '%s': %s" % (entry[1], e)
django.template.library.InvalidTemplateLibrary: Invalid template library specified. ImportError raised when trying to load 'crispy_forms.templatetags.crispy_forms_tags': No module named 'django.core.urlresolvers'

During handling of the above exception, another exception occurred:

Traceback (most recent call last):
  File "/home/marclane/Desktop/Targenda/targendaapi/venv/lib/python3.5/site-packages/django/template/utils.py", line 64, in __getitem__
    return self._engines[alias]
KeyError: 'django'

During handling of the above exception, another exception occurred:

Traceback (most recent call last):
  File "/home/marclane/Desktop/Targenda/targendaapi/venv/lib/python3.5/site-packages/django/template/backends/django.py", line 121, in get_package_libraries
    module = import_module(entry[1])
  File "/home/marclane/Desktop/Targenda/targendaapi/venv/lib/python3.5/importlib/__init__.py", line 126, in import_module
    return _bootstrap._gcd_import(name[level:], package, level)
  File "<frozen importlib._bootstrap>", line 986, in _gcd_import
  File "<frozen importlib._bootstrap>", line 969, in _find_and_load
  File "<frozen importlib._bootstrap>", line 958, in _find_and_load_unlocked
  File "<frozen importlib._bootstrap>", line 673, in _load_unlocked
  File "<frozen importlib._bootstrap_external>", line 665, in exec_module
  File "<frozen importlib._bootstrap>", line 222, in _call_with_frames_removed
  File "/home/marclane/Desktop/Targenda/targendaapi/venv/lib/python3.5/site-packages/crispy_forms/templatetags/crispy_forms_tags.py", line 11, in <module>
    from crispy_forms.helper import FormHelper
  File "/home/marclane/Desktop/Targenda/targendaapi/venv/lib/python3.5/site-packages/crispy_forms/helper.py", line 4, in <module>
    from django.core.urlresolvers import reverse, NoReverseMatch
ImportError: No module named 'django.core.urlresolvers'

During handling of the above exception, another exception occurred:

Traceback (most recent call last):
  File "/home/marclane/Desktop/Targenda/targendaapi/venv/lib/python3.5/site-packages/django/core/handlers/exception.py", line 35, in inner
    response = get_response(request)
  File "/home/marclane/Desktop/Targenda/targendaapi/venv/lib/python3.5/site-packages/django/utils/deprecation.py", line 95, in __call__
    response = self.get_response(request)
  File "/home/marclane/Desktop/Targenda/targendaapi/venv/lib/python3.5/site-packages/django/core/handlers/exception.py", line 37, in inner
    response = response_for_exception(request, exc)
  File "/home/marclane/Desktop/Targenda/targendaapi/venv/lib/python3.5/site-packages/django/core/handlers/exception.py", line 79, in response_for_exception
    response = get_exception_response(request, get_resolver(get_urlconf()), 400, exc)
  File "/home/marclane/Desktop/Targenda/targendaapi/venv/lib/python3.5/site-packages/django/core/handlers/exception.py", line 102, in get_exception_response
    response = handle_uncaught_exception(request, resolver, sys.exc_info())
  File "/home/marclane/Desktop/Targenda/targendaapi/venv/lib/python3.5/site-packages/django/core/handlers/exception.py", line 126, in handle_uncaught_exception
    return callback(request, **param_dict)
  File "/home/marclane/Desktop/Targenda/targendaapi/venv/lib/python3.5/site-packages/django/utils/decorators.py", line 142, in _wrapped_view
    response = view_func(request, *args, **kwargs)
  File "/home/marclane/Desktop/Targenda/targendaapi/venv/lib/python3.5/site-packages/django/views/defaults.py", line 69, in server_error
    template = loader.get_template(template_name)
  File "/home/marclane/Desktop/Targenda/targendaapi/venv/lib/python3.5/site-packages/django/template/loader.py", line 12, in get_template
    engines = _engine_list(using)
  File "/home/marclane/Desktop/Targenda/targendaapi/venv/lib/python3.5/site-packages/django/template/loader.py", line 66, in _engine_list
    return engines.all() if using is None else [engines[using]]
  File "/home/marclane/Desktop/Targenda/targendaapi/venv/lib/python3.5/site-packages/django/template/utils.py", line 88, in all
    return [self[alias] for alias in self]
  File "/home/marclane/Desktop/Targenda/targendaapi/venv/lib/python3.5/site-packages/django/template/utils.py", line 88, in <listcomp>
    return [self[alias] for alias in self]
  File "/home/marclane/Desktop/Targenda/targendaapi/venv/lib/python3.5/site-packages/django/template/utils.py", line 79, in __getitem__
    engine = engine_cls(params)
  File "/home/marclane/Desktop/Targenda/targendaapi/venv/lib/python3.5/site-packages/django/template/backends/django.py", line 25, in __init__
    options['libraries'] = self.get_templatetag_libraries(libraries)
  File "/home/marclane/Desktop/Targenda/targendaapi/venv/lib/python3.5/site-packages/django/template/backends/django.py", line 43, in get_templatetag_libraries
    libraries = get_installed_libraries()
  File "/home/marclane/Desktop/Targenda/targendaapi/venv/lib/python3.5/site-packages/django/template/backends/django.py", line 108, in get_installed_libraries
    for name in get_package_libraries(pkg):
  File "/home/marclane/Desktop/Targenda/targendaapi/venv/lib/python3.5/site-packages/django/template/backends/django.py", line 125, in get_package_libraries
    "trying to load '%s': %s" % (entry[1], e)
django.template.library.InvalidTemplateLibrary: Invalid template library specified. ImportError raised when trying to load 'crispy_forms.templatetags.crispy_forms_tags': No module named 'django.core.urlresolvers'

During handling of the above exception, another exception occurred:

Traceback (most recent call last):
  File "/home/marclane/Desktop/Targenda/targendaapi/venv/lib/python3.5/site-packages/django/template/utils.py", line 64, in __getitem__
    return self._engines[alias]
KeyError: 'django'

During handling of the above exception, another exception occurred:

Traceback (most recent call last):
  File "/home/marclane/Desktop/Targenda/targendaapi/venv/lib/python3.5/site-packages/django/template/backends/django.py", line 121, in get_package_libraries
    module = import_module(entry[1])
  File "/home/marclane/Desktop/Targenda/targendaapi/venv/lib/python3.5/importlib/__init__.py", line 126, in import_module
    return _bootstrap._gcd_import(name[level:], package, level)
  File "<frozen importlib._bootstrap>", line 986, in _gcd_import
  File "<frozen importlib._bootstrap>", line 969, in _find_and_load
  File "<frozen importlib._bootstrap>", line 958, in _find_and_load_unlocked
  File "<frozen importlib._bootstrap>", line 673, in _load_unlocked
  File "<frozen importlib._bootstrap_external>", line 665, in exec_module
  File "<frozen importlib._bootstrap>", line 222, in _call_with_frames_removed
  File "/home/marclane/Desktop/Targenda/targendaapi/venv/lib/python3.5/site-packages/crispy_forms/templatetags/crispy_forms_tags.py", line 11, in <module>
    from crispy_forms.helper import FormHelper
  File "/home/marclane/Desktop/Targenda/targendaapi/venv/lib/python3.5/site-packages/crispy_forms/helper.py", line 4, in <module>
    from django.core.urlresolvers import reverse, NoReverseMatch
ImportError: No module named 'django.core.urlresolvers'

During handling of the above exception, another exception occurred:

Traceback (most recent call last):
  File "/home/marclane/Desktop/Targenda/targendaapi/venv/lib/python3.5/site-packages/django/core/handlers/exception.py", line 35, in inner
    response = get_response(request)
  File "/home/marclane/Desktop/Targenda/targendaapi/venv/lib/python3.5/site-packages/django/utils/deprecation.py", line 95, in __call__
    response = self.get_response(request)
  File "/home/marclane/Desktop/Targenda/targendaapi/venv/lib/python3.5/site-packages/django/core/handlers/exception.py", line 37, in inner
    response = response_for_exception(request, exc)
  File "/home/marclane/Desktop/Targenda/targendaapi/venv/lib/python3.5/site-packages/django/core/handlers/exception.py", line 87, in response_for_exception
    response = handle_uncaught_exception(request, get_resolver(get_urlconf()), sys.exc_info())
  File "/home/marclane/Desktop/Targenda/targendaapi/venv/lib/python3.5/site-packages/django/core/handlers/exception.py", line 126, in handle_uncaught_exception
    return callback(request, **param_dict)
  File "/home/marclane/Desktop/Targenda/targendaapi/venv/lib/python3.5/site-packages/django/utils/decorators.py", line 142, in _wrapped_view
    response = view_func(request, *args, **kwargs)
  File "/home/marclane/Desktop/Targenda/targendaapi/venv/lib/python3.5/site-packages/django/views/defaults.py", line 69, in server_error
    template = loader.get_template(template_name)
  File "/home/marclane/Desktop/Targenda/targendaapi/venv/lib/python3.5/site-packages/django/template/loader.py", line 12, in get_template
    engines = _engine_list(using)
  File "/home/marclane/Desktop/Targenda/targendaapi/venv/lib/python3.5/site-packages/django/template/loader.py", line 66, in _engine_list
    return engines.all() if using is None else [engines[using]]
  File "/home/marclane/Desktop/Targenda/targendaapi/venv/lib/python3.5/site-packages/django/template/utils.py", line 88, in all
    return [self[alias] for alias in self]
  File "/home/marclane/Desktop/Targenda/targendaapi/venv/lib/python3.5/site-packages/django/template/utils.py", line 88, in <listcomp>
    return [self[alias] for alias in self]
  File "/home/marclane/Desktop/Targenda/targendaapi/venv/lib/python3.5/site-packages/django/template/utils.py", line 79, in __getitem__
    engine = engine_cls(params)
  File "/home/marclane/Desktop/Targenda/targendaapi/venv/lib/python3.5/site-packages/django/template/backends/django.py", line 25, in __init__
    options['libraries'] = self.get_templatetag_libraries(libraries)
  File "/home/marclane/Desktop/Targenda/targendaapi/venv/lib/python3.5/site-packages/django/template/backends/django.py", line 43, in get_templatetag_libraries
    libraries = get_installed_libraries()
  File "/home/marclane/Desktop/Targenda/targendaapi/venv/lib/python3.5/site-packages/django/template/backends/django.py", line 108, in get_installed_libraries
    for name in get_package_libraries(pkg):
  File "/home/marclane/Desktop/Targenda/targendaapi/venv/lib/python3.5/site-packages/django/template/backends/django.py", line 125, in get_package_libraries
    "trying to load '%s': %s" % (entry[1], e)
django.template.library.InvalidTemplateLibrary: Invalid template library specified. ImportError raised when trying to load 'crispy_forms.templatetags.crispy_forms_tags': No module named 'django.core.urlresolvers'
